<?xml version="1.0"?>
<robot name="a7_lite_right_visual">
  <material name="matte_graphite">
    <color rgba="0.16 0.17 0.19 1.0"/>
  </material>
  <material name="dark_graphite">
    <color rgba="0.06 0.07 0.08 1.0"/>
  </material>
  <material name="brushed_aluminum">
    <color rgba="0.72 0.74 0.76 1.0"/>
  </material>
  <material name="joint_black">
    <color rgba="0.02 0.025 0.03 1.0"/>
  </material>
  <material name="link_blue">
    <color rgba="0.05 0.28 0.85 1.0"/>
  </material>
  <material name="axis_gold">
    <color rgba="0.95 0.62 0.18 1.0"/>
  </material>
  <material name="tcp_green">
    <color rgba="0.0 0.8 0.35 1.0"/>
  </material>

  <link name="base_link">
    <visual>
      <origin xyz="0 0 -0.025" rpy="0 0 0"/>
      <geometry>
        <cylinder radius="0.095" length="0.05"/>
      </geometry>
      <material name="dark_graphite"/>
    </visual>
    <visual>
      <origin xyz="0 -0.055 0.012" rpy="0 0 0"/>
      <geometry>
        <box size="0.155 0.15 0.055"/>
      </geometry>
      <material name="brushed_aluminum"/>
    </visual>
    <visual>
      <origin xyz="0 -0.1435 0" rpy="1.5708 0 0"/>
      <geometry>
        <cylinder radius="0.062" length="0.075"/>
      </geometry>
      <material name="joint_black"/>
    </visual>
    <visual>
      <origin xyz="0 -0.1435 0" rpy="1.5708 0 0"/>
      <geometry>
        <cylinder radius="0.043" length="0.082"/>
      </geometry>
      <material name="axis_gold"/>
    </visual>
  </link>

  <link name="R1_Link">
    <visual>
      <origin xyz="0 0 0" rpy="1.5708 0 0"/>
      <geometry>
        <cylinder radius="0.058" length="0.06"/>
      </geometry>
      <material name="joint_black"/>
    </visual>
    <visual>
      <origin xyz="0.016 -0.037 0" rpy="1.5708 0 0"/>
      <geometry>
        <cylinder radius="0.035" length="0.082"/>
      </geometry>
      <material name="matte_graphite"/>
    </visual>
    <visual>
      <origin xyz="0.047 -0.036 0" rpy="0 0 0"/>
      <geometry>
        <box size="0.026 0.086 0.09"/>
      </geometry>
      <material name="brushed_aluminum"/>
    </visual>
    <visual>
      <origin xyz="-0.017 -0.036 0" rpy="0 0 0"/>
      <geometry>
        <box size="0.026 0.086 0.09"/>
      </geometry>
      <material name="brushed_aluminum"/>
    </visual>
    <visual>
      <origin xyz="0.03125 -0.0715 0" rpy="0 1.5708 0"/>
      <geometry>
        <cylinder radius="0.051" length="0.086"/>
      </geometry>
      <material name="joint_black"/>
    </visual>
  </link>
  <joint name="R1_JOINT" type="revolute">
    <origin xyz="0 -0.1435 0" rpy="0 0 0"/>
    <parent link="base_link"/>
    <child link="R1_Link"/>
    <axis xyz="0 1 0"/>
    <limit lower="-3.75" upper="2.18" effort="60" velocity="18.84"/>
  </joint>

  <link name="R2_Link">
    <visual>
      <origin xyz="0 0 0" rpy="0 1.5708 0"/>
      <geometry>
        <cylinder radius="0.048" length="0.08"/>
      </geometry>
      <material name="joint_black"/>
    </visual>
    <visual>
      <origin xyz="-0.03125 0 -0.0735" rpy="0 0 0"/>
      <geometry>
        <cylinder radius="0.033" length="0.147"/>
      </geometry>
      <material name="link_blue"/>
    </visual>
    <visual>
      <origin xyz="-0.03125 0 -0.0735" rpy="0 0 0"/>
      <geometry>
        <box size="0.055 0.034 0.136"/>
      </geometry>
      <material name="matte_graphite"/>
    </visual>
    <visual>
      <origin xyz="-0.03125 0 -0.147" rpy="0 0 0"/>
      <geometry>
        <sphere radius="0.044"/>
      </geometry>
      <material name="joint_black"/>
    </visual>
  </link>
  <joint name="R2_JOINT" type="revolute">
    <origin xyz="0.03125 -0.0715 0" rpy="0 0 0"/>
    <parent link="R1_Link"/>
    <child link="R2_Link"/>
    <axis xyz="-1 0 0"/>
    <limit lower="-0.19" upper="3.33" effort="60" velocity="18.84"/>
  </joint>

  <link name="R3_Link">
    <visual>
      <origin xyz="0 0 0" rpy="0 0 0"/>
      <geometry>
        <cylinder radius="0.042" length="0.052"/>
      </geometry>
      <material name="joint_black"/>
    </visual>
    <visual>
      <origin xyz="0 -0.0135 -0.063" rpy="0 0 0"/>
      <geometry>
        <cylinder radius="0.03" length="0.126"/>
      </geometry>
      <material name="brushed_aluminum"/>
    </visual>
    <visual>
      <origin xyz="0 -0.0135 -0.063" rpy="0 0 0"/>
      <geometry>
        <box size="0.05 0.03 0.116"/>
      </geometry>
      <material name="matte_graphite"/>
    </visual>
    <visual>
      <origin xyz="0 -0.027 -0.126" rpy="1.5708 0 0"/>
      <geometry>
        <cylinder radius="0.041" length="0.066"/>
      </geometry>
      <material name="joint_black"/>
    </visual>
  </link>
  <joint name="R3_JOINT" type="revolute">
    <origin xyz="-0.03125 0 -0.147" rpy="0 0 0"/>
    <parent link="R2_Link"/>
    <child link="R3_Link"/>
    <axis xyz="0 0 1"/>
    <limit lower="-2.26" upper="2.26" effort="17" velocity="37.68"/>
  </joint>

  <link name="R4_Link">
    <visual>
      <origin xyz="0 0 0" rpy="1.5708 0 0"/>
      <geometry>
        <cylinder radius="0.04" length="0.062"/>
      </geometry>
      <material name="joint_black"/>
    </visual>
    <visual>
      <origin xyz="0 0.0135 -0.068" rpy="0 0 0"/>
      <geometry>
        <cylinder radius="0.027" length="0.136"/>
      </geometry>
      <material name="link_blue"/>
    </visual>
    <visual>
      <origin xyz="0 0.0135 -0.068" rpy="0 0 0"/>
      <geometry>
        <box size="0.046 0.027 0.123"/>
      </geometry>
      <material name="matte_graphite"/>
    </visual>
    <visual>
      <origin xyz="0 0.027 -0.136" rpy="0 0 0"/>
      <geometry>
        <cylinder radius="0.037" length="0.05"/>
      </geometry>
      <material name="joint_black"/>
    </visual>
  </link>
  <joint name="R4_JOINT" type="revolute">
    <origin xyz="0 -0.027 -0.126" rpy="0 0 0"/>
    <parent link="R3_Link"/>
    <child link="R4_Link"/>
    <axis xyz="0 1 0"/>
    <limit lower="-1.74" upper="0.78" effort="36" velocity="10.47"/>
  </joint>

  <link name="R5_Link">
    <visual>
      <origin xyz="0 0 0" rpy="0 0 0"/>
      <geometry>
        <cylinder radius="0.036" length="0.046"/>
      </geometry>
      <material name="joint_black"/>
    </visual>
    <visual>
      <origin xyz="0 -0.014 -0.02175" rpy="1.5708 0 0"/>
      <geometry>
        <cylinder radius="0.026" length="0.052"/>
      </geometry>
      <material name="brushed_aluminum"/>
    </visual>
    <visual>
      <origin xyz="0 -0.028 -0.0435" rpy="1.5708 0 0"/>
      <geometry>
        <cylinder radius="0.034" length="0.054"/>
      </geometry>
      <material name="joint_black"/>
    </visual>
    <visual>
      <origin xyz="0 -0.014 -0.022" rpy="0 0 0"/>
      <geometry>
        <box size="0.044 0.024 0.065"/>
      </geometry>
      <material name="matte_graphite"/>
    </visual>
  </link>
  <joint name="R5_JOINT" type="revolute">
    <origin xyz="0 0.027 -0.136" rpy="0 0 0"/>
    <parent link="R4_Link"/>
    <child link="R5_Link"/>
    <axis xyz="0 0 1"/>
    <limit lower="-2.96" upper="2.96" effort="14" velocity="27.21"/>
  </joint>

  <link name="R6_Link">
    <visual>
      <origin xyz="0 0 0" rpy="1.5708 0 0"/>
      <geometry>
        <cylinder radius="0.034" length="0.052"/>
      </geometry>
      <material name="joint_black"/>
    </visual>
    <visual>
      <origin xyz="0.014 0.014 -0.0375" rpy="0 0 0"/>
      <geometry>
        <cylinder radius="0.023" length="0.075"/>
      </geometry>
      <material name="link_blue"/>
    </visual>
    <visual>
      <origin xyz="0.014 0.014 -0.0375" rpy="0 0 0"/>
      <geometry>
        <box size="0.035 0.028 0.066"/>
      </geometry>
      <material name="matte_graphite"/>
    </visual>
    <visual>
      <origin xyz="0.028 0.028 -0.075" rpy="0 1.5708 0"/>
      <geometry>
        <cylinder radius="0.031" length="0.052"/>
      </geometry>
      <material name="joint_black"/>
    </visual>
  </link>
  <joint name="R6_JOINT" type="revolute">
    <origin xyz="0 -0.028 -0.0435" rpy="0 0 0"/>
    <parent link="R5_Link"/>
    <child link="R6_Link"/>
    <axis xyz="0 1 0"/>
    <limit lower="-1.57" upper="1.57" effort="14" velocity="27.21"/>
  </joint>

  <link name="R7_Link">
    <visual>
      <origin xyz="0 0 0" rpy="0 1.5708 0"/>
      <geometry>
        <cylinder radius="0.031" length="0.05"/>
      </geometry>
      <material name="joint_black"/>
    </visual>
    <visual>
      <origin xyz="0 0 -0.04" rpy="0 0 0"/>
      <geometry>
        <cylinder radius="0.026" length="0.08"/>
      </geometry>
      <material name="brushed_aluminum"/>
    </visual>
    <visual>
      <origin xyz="0 0 -0.081" rpy="0 0 0"/>
      <geometry>
        <cylinder radius="0.036" length="0.014"/>
      </geometry>
      <material name="joint_black"/>
    </visual>
    <visual>
      <origin xyz="0 0 -0.091" rpy="0 0 0"/>
      <geometry>
        <cylinder radius="0.028" length="0.012"/>
      </geometry>
      <material name="axis_gold"/>
    </visual>
  </link>
  <joint name="R7_JOINT" type="revolute">
    <origin xyz="0.028 0.028 -0.075" rpy="0 0 0"/>
    <parent link="R6_Link"/>
    <child link="R7_Link"/>
    <axis xyz="-1 0 0"/>
    <limit lower="-1.57" upper="1.57" effort="14" velocity="27.21"/>
  </joint>

  <link name="tcp_link">
    <visual>
      <origin xyz="0 0 0" rpy="0 0 0"/>
      <geometry>
        <sphere radius="0.018"/>
      </geometry>
      <material name="tcp_green"/>
    </visual>
    <visual>
      <origin xyz="0 0 0.018" rpy="0 0 0"/>
      <geometry>
        <cylinder radius="0.018" length="0.036"/>
      </geometry>
      <material name="tcp_green"/>
    </visual>
  </link>
  <joint name="tcp_fixed_joint" type="fixed">
    <origin xyz="0 0 -0.08" rpy="0 0 0"/>
    <parent link="R7_Link"/>
    <child link="tcp_link"/>
  </joint>
</robot>
